Workbook

Sheet Leyenda
A1: Accesorios de polietileno · La Tienda del Jardín · plantilla para la base de datos de PIPING
A3: Qué contiene
A4: • Hoja «Accesorios»: una fila por pieza y medida, con los tipos y medidas leídos de latiendadeljardin.com (categoría 118 «Piezas de polietileno»).
A5: • Hoja «Parámetros»: medidas del tubo PE de referencia, diámetros de paso de los insertos y de las roscas, fT de Crane y coeficientes por tipo de pieza.
A6: • Hoja «Packs»: los packs de 4 o 5 unidades y los kits de riego de la tienda, enlazados a su pieza, con el precio por unidad.
A7: • Hoja «Fuentes»: de dónde sale cada dato.
A9: Colores
A10: • Texto azul: dato introducido (de la tienda o supuesto). Texto negro: fórmula, no la toques.
A11: • Precio: el de la pieza suelta es el «desde» de la tienda (medida más pequeña); el de pack es el de esa medida.
A12: • Fondo amarillo: dato que hay que verificar o completar. Sobre todo: diámetros de paso, roscas equivalentes y precio por medida.
A14: Cómo se calcula el K (Crane TP-410M, fórmulas 5 y 6, θ = 180°: estrechamiento brusco del inserto)
A15: K (referido a la velocidad en el tubo de salida, Dint2) = [K1 + 0,5·(1 − (dp/Dint1)²) + (1 − (dp/Dint2)²)²] · (Dint2/dp)⁴
... A27: 4. Cuando esté revisada, pásamela y genero el SQL para Supabase (13_accesorios_pe.sql). Saldrá en Librerías › Accesorios, filtrada como plástico.

Sheet Parámetros
A1: Parámetros del cálculo
A3: Tubo PE de referencia: PE100 SDR 11 (PN 16) · EN 12201-2
A4: d (mm) | B4: Rosca BSP equivalente | C4: e (mm) | D4: Dint tubo (mm) | E4: d paso inserto (mm) | F4: NPS para fT | G4: fT (Crane)
A5: 20 | B5: 1/2" | C5: 2 | D5: =A5-2*C5 -> 16 | E5: 13 | F5: 1/2" | G5: 0.027
A6: 25 | B6: 3/4" | C6: 2.3 | D6: =A6-2*C6 -> 20.4 | E6: 17 | F6: 3/4" | G6: 0.025
A7: 32 | B7: 1" | C7: 2.9 | D7: =A7-2*C7 -> 26.2 | E7: 22 | F7: 1" | G7: 0.023
A8: 40 | B8: 1 1/4" | C8: 3.7 | D8: =A8-2*C8 -> 32.6 | E8: 28 | F8: 1 1/4" | G8: 0.022
A9: 50 | B9: 1 1/2" | C9: 4.6 | D9: =A9-2*C9 -> 40.8 | E9: 35 | F9: 1 1/2" | G9: 0.021
A10: 63 | B10: 2" | C10: 5.8 | D10: =A10-2*C10 -> 51.4 | E10: 45 | F10: 2" | G10: 0.019
A11: 75 | B11: 2 1/2" | C11: 6.8 | D11: =A11-2*C11 -> 61.4 | E11: 54 | F11: 2 1/2" | G11: 0.018
A12: 90 | B12: 3" | C12: 8.2 | D12: =A12-2*C12 -> 73.6 | E12: 66 | F12: 3" | G12: 0.018
A14: Piezas roscadas BSP: diámetro de paso de referencia
A15: Rosca | B15: d paso (mm) | C15: fT (Crane)
A16: 1/2" | B16: 15.8 | C16: 0.027
A17: 3/4" | B17: 20.9 | C17: 0.025
A18: 1" | B18: 26.6 | C18: 0.023
A19: 1 1/4" | B19: 35.1 | C19: 0.022
A20: 1 1/2" | B20: 40.9 | C20: 0.021
A21: 2" | B21: 52.5 | C21: 0.019
A22: 2 1/2" | B22: 62.7 | C22: 0.018
A23: 3" | B23: 77.9 | C23: 0.018
A25: Coeficientes por tipo de pieza: K1 = n·fT (Crane A-29) y K adicional fijo
A26: Clave | B26: Pieza | C26: n paso | D26: n derivación | E26: K adicional fijo | F26: Fuente
A27: MANG | B27: Manguito / enlace de compresión (cuerpo recto) | C27: 0 | E27: 0 | F27: Solo pérdida del inserto (Crane fórm. 6)
A28: CODO | B28: Codo 90° (cuerpo de codo estándar) | C28: 30 | E28: 0 | F28: Crane A-29: codo estándar 90° = 30·fT
A29: TE | B29: Te (paso directo / derivación) | C29: 20 | D29: 60 | E29: 0 | F29: Crane A-29: te paso 20·fT, derivación 60·fT
A30: ROSC | B30: Pieza roscada recta (machón, manguito, tuerca) | C30: 0 | E30: 0.04 | F30: Perry: manguito / unión 0,04
A31: DEP | B31: Pasamuros / adaptador de depósito | C31: 0 | E31: 0.5 | F31: Crane A-30: entrada a ras 0,5 · salida 1,0

Sheet Packs
A1: Ref. pack | B1: Artículo (tienda) | C1: Unidades | D1: Código de la pieza | E1: Precio pack (€, IVA incl.) | F1: Precio por unidad (€) | G1: K paso de la pieza | H1: URL | I1: Notas
A2: 5220_x4 | B2: Pack 4 Manguito Polietileno 20mm (Aenor) | C2: 4 | D2: PE-MI-20 | E2: 12.95 | F2: =IF(E2="","",E2/C2) -> 3.2375 | G2: =IF(D2="","",IFERROR(INDEX(Accesorios!$S$2:$S$129,MATCH(D2,Accesorios!$A$2:$A$129,0)),"")) -> 0.65491404 | H2: https://latiendadeljardin.com/es/piezas-de-polietileno/3193-enlace-manguito-polietileno-20mm-pack4.html
A3: 5225_x4 | B3: Pack 4 Manguito Polietileno 25mm (Aenor) | C3: 4 | D3: PE-MI-25 | E3: 11.95 | F3: =IF(E3="","",E3/C3) -> 2.9875 | G3: =IF(D3="","",IFERROR(INDEX(Accesorios!$S$2:$S$129,MATCH(D3,Accesorios!$A$2:$A$129,0)),"")) -> 0.5104 | H3: https://latiendadeljardin.com/es/piezas-de-polietileno/3195-enlace-manguito-polietileno-25mm-pack4.html
A4: 5232_x4 | B4: Pack 4 Manguito Polietileno 32mm (Aenor) | C4: 4 | D4: PE-MI-32 | E4: 14.95 | F4: =IF(E4="","",E4/C4) -> 3.7375 | G4: =IF(D4="","",IFERROR(INDEX(Accesorios!$S$2:$S$129,MATCH(D4,Accesorios!$A$2:$A$129,0)),"")) -> 0.47154997 | H4: https://latiendadeljardin.com/es/piezas-de-polietileno/3196-enlace-manguito-polietileno-32mm-pack4-8420082100900.html
A5: 5240_x4 | B5: Pack 4 Manguito Polietileno 40mm (Aenor) | C5: 4 | D5: PE-MI-40 | E5: 24.95 | F5: =IF(E5="","",E5/C5) -> 6.2375 | G5: =IF(D5="","",IFERROR(INDEX(Accesorios!$S$2:$S$129,MATCH(D5,Accesorios!$A$2:$A$129,0)),"")) -> 0.36741629 | H5: https://latiendadeljardin.com/es/piezas-de-polietileno/3197-enlace-manguito-polietileno-40mm-pack4.html
A6: 5250_x4 | B6: Pack 4 Manguito Polietileno 50mm (Aenor) | C6: 4 | D6: PE-MI-50 | E6: 37.95 | F6: =IF(E6="","",E6/C6) -> 9.4875 | G6: =IF(D6="","",IFERROR(INDEX(Accesorios!$S$2:$S$129,MATCH(D6,Accesorios!$A$2:$A$129,0)),"")) -> 0.37264773 | H6: https://latiendadeljardin.com/es/piezas-de-polietileno/3198-enlace-manguito-polietileno-50mm-pack4-8420082100924.html
A7: 5263_x4 | B7: Pack 4 Manguito Polietileno 63mm (Aenor) | C7: 4 | D7: PE-MI-63 | E7: 58.95 | F7: =IF(E7="","",E7/C7) -> 14.7375 | G7: =IF(D7="","",IFERROR(INDEX(Accesorios!$S$2:$S$129,MATCH(D7,Accesorios!$A$2:$A$129,0)),"")) -> 0.29157298 | H7: https://latiendadeljardin.com/es/piezas-de-polietileno/3199-enlace-manguito-polietileno-63mm-pack4.html
A8: 5275_x5 | B8: Pack 5 Manguito Polietileno 75mm (Aenor) | C8: 5 | D8: PE-MI-75 | E8: 88.95 | F8: =IF(E8="","",E8/C8) -> 17.79 | G8: =IF(D8="","",IFERROR(INDEX(Accesorios!$S$2:$S$129,MATCH(D8,Accesorios!$A$2:$A$129,0)),"")) -> 0.27507113 | H8: https://latiendadeljardin.com/es/piezas-de-polietileno/3200-enlace-manguito-polietileno-75mm-pack5.html
A9: 5290_x5 | B9: Pack 5 Manguito Polietileno 90mm (Aenor) | C9: 5 | D9: PE-MI-90 | E9: 130.95 | F9: =IF(E9="","",E9/C9) -> 26.19 | G9: =IF(D9="","",IFERROR(INDEX(Accesorios!$S$2:$S$129,MATCH(D9,Accesorios!$A$2:$A$129,0)),"")) -> 0.21076578 | H9: https://latiendadeljardin.com/es/piezas-de-polietileno/3201-enlace-manguito-polietileno-90mm-pack5.html
A10: MR2520_x4 | B10: Pack 4 Manguito Reducido Polietileno 25 a 20 mm (Aenor) | C10: 4 | D10: PE-MR-25x20 | E10: 9.95 | F10: =IF(E10="","",E10/C10) -> 2.4875 | G10: =IF(D10="","",IFERROR(INDEX(Accesorios!$S$2:$S$129,MATCH(D10,Accesorios!$A$2:$A$129,0)),"")) -> 0.94639957 | H10: https://latiendadeljardin.com/es/piezas-de-polietileno/3256-enlace-manguito-reducido-25-20mm-pack4.html
A11: MR3225_x4 | B11: Pack 4 Manguito Reducido Polietileno 32 a 25 mm (Aenor) | C11: 4 | D11: PE-MR-32x25 | E11: 12.95 | F11: =IF(E11="","",E11/C11) -> 3.2375 | G11: =IF(D11="","",IFERROR(INDEX(Accesorios!$S$2:$S$129,MATCH(D11,Accesorios!$A$2:$A$129,0)),"")) -> 0.79389397 | H11: https://latiendadeljardin.com/es/piezas-de-polietileno/3257-enlace-manguito-reducido-32-25mm-pack4.html
A12: MR4032_x4 | B12: Pack 4 Manguito Reducido Polietileno 40 a 32 mm (Aenor) | C12: 4 | D12: PE-MR-40x32 | E12: 18.95 | F12: =IF(E12="","",E12/C12) -> 4.7375 | G12: =IF(D12="","",IFERROR(INDEX(Accesorios!$S$2:$S$129,MATCH(D12,Accesorios!$A$2:$A$129,0)),"")) -> 0.72265148 | H12: https://latiendadeljardin.com/es/piezas-de-polietileno/3258-enlace-manguito-reducido-40-32mm-pack4.html
A13: MR5040_x4 | B13: Pack 4 Manguito Reducido Polietileno 50 a 40 mm (Aenor) | C13: 4 | D13: PE-MR-50x40 | E13: 26.95 | F13: =IF(E13="","",E13/C13) -> 6.7375 | G13: =IF(D13="","",IFERROR(INDEX(Accesorios!$S$2:$S$129,MATCH(D13,Accesorios!$A$2:$A$129,0)),"")) -> 0.61247984 | H13: https://latiendadeljardin.com/es/piezas-de-polietileno/3259-enlace-manguito-reducido-50-40mm-pack4.html
... A16: MR9075_x4 | B16: Pack 4 Manguito Reducido Polietileno 90 a 75 mm (Aenor) | C16: 4 | D16: PE-MR-90x75 | E16: 109.95 | F16: =IF(E16="","",E16/C16) -> 27.4875 | G16: =IF(D16="","",IFERROR(INDEX(Accesorios!$S$2:$S$129,MATCH(D16,Accesorios!$A$2:$A$129,0)),"")) -> 0.47161395 | H16: https://latiendadeljardin.com/es/piezas-de-polietileno/3262-enlace-manguito-reducido-90-75mm-pack4.html
A17: 5920_x4 | B17: Pack 4 Tapón Polietileno 20mm (Aenor) | C17: 4 | D17: PE-TF-20 | F17: =IF(E17="","",E17/C17) | G17: =IF(D17="","",IFERROR(INDEX(Accesorios!$S$2:$S$129,MATCH(D17,Accesorios!$A$2:$A$129,0)),"")) -> 0 | H17: https://latiendadeljardin.com/es/piezas-de-polietileno/3153-tapon-final-polietileno-20mm-pack4.html | I17: No confirmado: no se pudo leer en la tienda
A18: 5925_x4 | B18: Pack 4 Tapón Polietileno 25mm (Aenor) | C18: 4 | D18: PE-TF-25 | E18: 8.95 | F18: =IF(E18="","",E18/C18) -> 2.2375 | G18: =IF(D18="","",IFERROR(INDEX(Accesorios!$S$2:$S$129,MATCH(D18,Accesorios!$A$2:$A$129,0)),"")) -> 0 | H18: https://latiendadeljardin.com/es/piezas-de-polietileno/3154-tapon-final-polietileno-25mm-pack4.html
A19: 5932_x4 | B19: Pack 4 Tapón Polietileno 32mm (Aenor) | C19: 4 | D19: PE-TF-32 | E19: 11.95 | F19: =IF(E19="","",E19/C19) -> 2.9875 | G19: =IF(D19="","",IFERROR(INDEX(Accesorios!$S$2:$S$129,MATCH(D19,Accesorios!$A$2:$A$129,0)),"")) -> 0 | H19: https://latiendadeljardin.com/es/piezas-de-polietileno/3155-tapon-final-polietileno-32mm-pack4.html
A20: 5940_x4 | B20: Pack 4 Tapón Polietileno 40mm (Aenor) | C20: 4 | D20: PE-TF-40 | F20: =IF(E20="","",E20/C20) | G20: =IF(D20="","",IFERROR(INDEX(Accesorios!$S$2:$S$129,MATCH(D20,Accesorios!$A$2:$A$129,0)),"")) -> 0 | H20: https://latiendadeljardin.com/es/piezas-de-polietileno/3156-tapon-final-polietileno-40mm-pack4.html | I20: No confirmado: no se pudo leer en la tienda
A21: 5950_x4 | B21: Pack 4 Tapón Polietileno 50mm (Aenor) | C21: 4 | D21: PE-TF-50 | E21: 21.95 | F21: =IF(E21="","",E21/C21) -> 5.4875 | G21: =IF(D21="","",IFERROR(INDEX(Accesorios!$S$2:$S$129,MATCH(D21,Accesorios!$A$2:$A$129,0)),"")) -> 0 | H21: https://latiendadeljardin.com/es/piezas-de-polietileno/3157-tapon-final-polietileno-50mm-pack4.html
A22: 5963_x4 | B22: Pack 4 Tapón Polietileno 63mm (Aenor) | C22: 4 | D22: PE-TF-63 | E22: 30.95 | F22: =IF(E22="","",E22/C22) -> 7.7375 | G22: =IF(D22="","",IFERROR(INDEX(Accesorios!$S$2:$S$129,MATCH(D22,Accesorios!$A$2:$A$129,0)),"")) -> 0 | H22: https://latiendadeljardin.com/es/piezas-de-polietileno/3158-tapon-final-polietileno-63mm-pack4.html
A23: 5975_x4 | B23: Pack 4 Tapón Polietileno 75mm (Aenor) | C23: 4 | D23: PE-TF-75 | E23: 50.95 | F23: =IF(E23="","",E23/C23) -> 12.7375 | G23: =IF(D23="","",IFERROR(INDEX(Accesorios!$S$2:$S$129,MATCH(D23,Accesorios!$A$2:$A$129,0)),"")) -> 0 | H23: https://latiendadeljardin.com/es/piezas-de-polietileno/3159-tapon-final-polietileno-75mm-pack4.html
A24: 5120_x4 | B24: Pack 4 Enlace Hembra Polietileno 20mm x 1/2" (Aenor) | C24: 4 | D24: PE-EH-20 | E24: 5.95 | F24: =IF(E24="","",E24/C24) -> 1.4875 | G24: =IF(D24="","",IFERROR(INDEX(Accesorios!$S$2:$S$129,MATCH(D24,Accesorios!$A$2:$A$129,0)),"")) -> 0.65491404 | H24: https://latiendadeljardin.com/es/piezas-de-polietileno/3347-enlace-hembra-pe-20mm-pack4.html
A25: 5125_x4 | B25: Pack 4 Enlace Hembra Polietileno 25mm x 3/4" (Aenor) | C25: 4 | D25: PE-EH-25 | E25: 7.95 | F25: =IF(E25="","",E25/C25) -> 1.9875 | G25: =IF(D25="","",IFERROR(INDEX(Accesorios!$S$2:$S$129,MATCH(D25,Accesorios!$A$2:$A$129,0)),"")) -> 0.5104 | H25: https://latiendadeljardin.com/es/piezas-de-polietileno/3348-enlace-hembra-pe-25mm-pack4.html
A26: 5132_x4 | B26: Pack 4 Enlace Hembra Polietileno 32mm x 1" (Aenor) | C26: 4 | D26: PE-EH-32 | E26: 10.95 | F26: =IF(E26="","",E26/C26) -> 2.7375 | G26: =IF(D26="","",IFERROR(INDEX(Accesorios!$S$2:$S$129,MATCH(D26,Accesorios!$A$2:$A$129,0)),"")) -> 0.47154997 | H26: https://latiendadeljardin.com/es/piezas-de-polietileno/3349-enlace-hembra-pe-32mm-pack4.html
A27: 5140_x4 | B27: Pack 4 Enlace Hembra Polietileno 40mm x 1 1/4" (Aenor) | C27: 4 | D27: PE-EH-40 | E27: 15.95 | F27: =IF(E27="","",E27/C27) -> 3.9875 | G27: =IF(D27="","",IFERROR(INDEX(Accesorios!$S$2:$S$129,MATCH(D27,Accesorios!$A$2:$A$129,0)),"")) -> 0.36741629 | H27: https://latiendadeljardin.com/es/piezas-de-polietileno/3350-enlace-hembra-pe-40mm-pack4.html
A28: 5150_x4 | B28: Pack 4 Enlace Hembra Polietileno 50mm x 1 1/2" (Aenor) | C28: 4 | D28: PE-EH-50 | E28: 20.95 | F28: =IF(E28="","",E28/C28) -> 5.2375 | G28: =IF(D28="","",IFERROR(INDEX(Accesorios!$S$2:$S$129,MATCH(D28,Accesorios!$A$2:$A$129,0)),"")) -> 0.37264773 | H28: https://latiendadeljardin.com/es/piezas-de-polietileno/3351-enlace-hembra-pe-50mm-pack4.html
A29: 5163_x4 | B29: Pack 4 Enlace Hembra Polietileno 63mm x 2" (Aenor) | C29: 4 | D29: PE-EH-63 | E29: 31.95 | F29: =IF(E29="","",E29/C29) -> 7.9875 | G29: =IF(D29="","",IFERROR(INDEX(Accesorios!$S$2:$S$129,MATCH(D29,Accesorios!$A$2:$A$129,0)),"")) -> 0.29157298 | H29: https://latiendadeljardin.com/es/piezas-de-polietileno/3352-enlace-hembra-pe-63mm-pack4.html
A30: 5175_x4 | B30: Pack 4 Enlace Hembra Polietileno 75mm x 2 1/2" (Aenor) | C30: 4 | D30: PE-EH-75 | E30: 61.95 | F30: =IF(E30="","",E30/C30) -> 15.4875 | G30: =IF(D30="","",IFERROR(INDEX(Accesorios!$S$2:$S$129,MATCH(D30,Accesorios!$A$2:$A$129,0)),"")) -> 0.27507113 | H30: https://latiendadeljardin.com/es/piezas-de-polietileno/3353-enlace-hembra-pe-75mm-pack4.html
A31: 5190_x4 | B31: Pack 4 Enlace Hembra Polietileno 90mm x 3" (Aenor) | C31: 4 | D31: PE-EH-90 | E31: 75.95 | F31: =IF(E31="","",E31/C31) -> 18.9875 | G31: =IF(D31="","",IFERROR(INDEX(Accesorios!$S$2:$S$129,MATCH(D31,Accesorios!$A$2:$A$129,0)),"")) -> 0.21076578 | H31: https://latiendadeljardin.com/es/piezas-de-polietileno/3354-enlace-hembra-pe-90mm-pack4.html
A32: 5020_x4 | B32: Pack 4 Enlace Macho Polietileno 20mm x 1/2" (Aenor) | C32: 4 | D32: PE-EM-20 | E32: 6.95 | F32: =IF(E32="","",E32/C32) -> 1.7375 | G32: =IF(D32="","",IFERROR(INDEX(Accesorios!$S$2:$S$129,MATCH(D32,Accesorios!$A$2:$A$129,0)),"")) -> 0.65491404 | H32: https://latiendadeljardin.com/es/piezas-de-polietileno/16513-4-enlace-macho-polietileno-20mm.html
... A36: 5050_x4 | B36: Pack 4 Enlace Macho Polietileno 50mm x 1 1/2" (Aenor) | C36: 4 | D36: PE-EM-50 | E36: 22.95 | F36: =IF(E36="","",E36/C36) -> 5.7375 | G36: =IF(D36="","",IFERROR(INDEX(Accesorios!$S$2:$S$129,MATCH(D36,Accesorios!$A$2:$A$129,0)),"")) -> 0.37264773 | H36: https://latiendadeljardin.com/es/piezas-de-polietileno/16517-4-enlace-macho-polietileno-50mm.html
A37: 5063_x4 | B37: Pack 4 Enlace Macho Polietileno 63mm x 2" (Aenor) | C37: 4 | D37: PE-EM-63 | F37: =IF(E37="","",E37/C37) | G37: =IF(D37="","",IFERROR(INDEX(Accesorios!$S$2:$S$129,MATCH(D37,Accesorios!$A$2:$A$129,0)),"")) -> 0.29157298 | H37: https://latiendadeljardin.com/es/piezas-de-polietileno/16518-4-enlace-macho-polietileno-63mm.html | I37: No confirmado: no se pudo leer en la tienda
A38: 5075_x4 | B38: Pack 4 Enlace Macho Polietileno 75mm x 2 1/2" (Aenor) | C38: 4 | D38: PE-EM-75 | E38: 57.95 | F38: =IF(E38="","",E38/C38) -> 14.4875 | G38: =IF(D38="","",IFERROR(INDEX(Accesorios!$S$2:$S$129,MATCH(D38,Accesorios!$A$2:$A$129,0)),"")) -> 0.27507113 | H38: https://latiendadeljardin.com/es/piezas-de-polietileno/16519-4-enlace-macho-polietileno-75mm.html
A39: 5090_x4 | B39: Pack 4 Enlace Macho Polietileno 90mm x 3" (Aenor) | C39: 4 | D39: PE-EM-90 | E39: 81.95 | F39: =IF(E39="","",E39/C39) -> 20.4875 | G39: =IF(D39="","",IFERROR(INDEX(Accesorios!$S$2:$S$129,MATCH(D39,Accesorios!$A$2:$A$129,0)),"")) -> 0.21076578 | H39: https://latiendadeljardin.com/es/piezas-de-polietileno/16520-4-enlace-macho-polietileno-90mm.html
A40: 5420_x4 | B40: Pack 4 Te Polietileno 20mm (Aenor) | C40: 4 | D40: PE-TI-20 | E40: 10.95 | F40: =IF(E40="","",E40/C40) -> 2.7375 | G40: =IF(D40="","",IFERROR(INDEX(Accesorios!$S$2:$S$129,MATCH(D40,Accesorios!$A$2:$A$129,0)),"")) -> 1.8939967 | H40: https://latiendadeljardin.com/es/piezas-de-polietileno/16521-4-te-polietileno-20mm.html
A41: 5425_x4 | B41: Pack 4 Te Polietileno 25mm (Aenor) | C41: 4 | D41: PE-TI-25 | E41: 14.95 | F41: =IF(E41="","",E41/C41) -> 3.7375 | G41: =IF(D41="","",IFERROR(INDEX(Accesorios!$S$2:$S$129,MATCH(D41,Accesorios!$A$2:$A$129,0)),"")) -> 1.5472 | H41: https://latiendadeljardin.com/es/piezas-de-polietileno/16522-4-te-polietileno-25mm.html
A42: 5432_x4 | B42: Pack 4 Te Polietileno 32mm (Aenor) | C42: 4 | D42: PE-TI-32 | E42: 17.95 | F42: =IF(E42="","",E42/C42) -> 4.4875 | G42: =IF(D42="","",IFERROR(INDEX(Accesorios!$S$2:$S$129,MATCH(D42,Accesorios!$A$2:$A$129,0)),"")) -> 1.3968281 | H42: https://latiendadeljardin.com/es/piezas-de-polietileno/16523-4-te-polietileno-32mm.html
A43: 5440_x4 | B43: Pack 4 Te Polietileno 40mm (Aenor) | C43: 4 | D43: PE-TI-40 | E43: 29.95 | F43: =IF(E43="","",E43/C43) -> 7.4875 | G43: =IF(D43="","",IFERROR(INDEX(Accesorios!$S$2:$S$129,MATCH(D43,Accesorios!$A$2:$A$129,0)),"")) -> 1.1759366 | H43: https://latiendadeljardin.com/es/piezas-de-polietileno/16524-4-te-polietileno-40mm.html
A44: 5450_x4 | B44: Pack 4 Te Polietileno 50mm (Aenor) | C44: 4 | D44: PE-TI-50 | E44: 38.95 | F44: =IF(E44="","",E44/C44) -> 9.7375 | G44: =IF(D44="","",IFERROR(INDEX(Accesorios!$S$2:$S$129,MATCH(D44,Accesorios!$A$2:$A$129,0)),"")) -> 1.1482119 | H44: https://latiendadeljardin.com/es/piezas-de-polietileno/16525-4-te-polietileno-50mm.html
A45: 5463_x4 | B45: Pack 4 Te Polietileno 63mm (Aenor) | C45: 4 | D45: PE-TI-63 | E45: 45.95 | F45: =IF(E45="","",E45/C45) -> 11.4875 | G45: =IF(D45="","",IFERROR(INDEX(Accesorios!$S$2:$S$129,MATCH(D45,Accesorios!$A$2:$A$129,0)),"")) -> 0.93839682 | H45: https://latiendadeljardin.com/es/piezas-de-polietileno/16526-4-te-polietileno-63mm.html
...

Sheet Accesorios
A1: Código | B1: Artículo (tienda) | C1: Ref. tienda | D1: Subtipo PIPING | E1: Variante | F1: Conexión | G1: d1 (mm o ") | H1: d2 (mm o ") | I1: Rosca BSP | J1: PN (bar) | K1: Material | L1: Dint 1 (mm) | M1: Dint 2 (mm) | N1: d paso (mm) | O1: d paso deriv. (mm) | P1: fT | Q1: K1 paso | R1: K1 deriv. | S1: K paso (ref. salida) | T1: K derivación (ref. deriv.) | U1: K sentido inverso | V1: Origen del K | W1: Precio (€, IVA incl.) | X1: URL | Y1: Notas | Z1: Clave K | AA1: Tabla | AB1: Precio por unidad en pack (€) | AC1: Packs disponibles
A2: PE-MI-20 | B2: Manguito igual PE | C2: 5220 | D2: manguito | E2: Manguito de compresión igual | F2: Compresión × compresión | G2: 20 | J2: 16 | K2: PP (cuerpo) · compresión para tubo PE | L2: =INDEX(Parámetros!$D$5:$D$12,MATCH(G2,Parámetros!$A$5:$A$12,0)) -> 16 | M2: =INDEX(Parámetros!$D$5:$D$12,MATCH(IF(H2="",G2,H2),Parámetros!$A$5:$A$12,0)) -> 16 | N2: =INDEX(Parámetros!$E$5:$E$12,MATCH(G2,Parámetros!$A$5:$A$12,0)) -> 13 | P2: =INDEX(Parámetros!$G$5:$G$12,MATCH(G2,Parámetros!$A$5:$A$12,0)) -> 0.027 | Q2: =IF(Z2="","",INDEX(Parámetros!$C$27:$C$31,MATCH(Z2,Parámetros!$A$27:$A$31,0))*P2) -> 0 | S2: =(Q2+0.5*(1-(N2/L2)^2)+(1-(N2/M2)^2)^2)*(M2/N2)^4+IF(Z2="",0,INDEX(Parámetros!$E$27:$E$31,MATCH(Z2,Parámetros!$A$27:$A$31,0))) -> 0.65491404 | U2: =IF(H2="","",(Q2+0.5*(1-(N2/M2)^2)+(1-(N2/L2)^2)^2)*(M2/N2)^4+IF(Z2="",0,INDEX(Parámetros!$E$27:$E$31,MATCH(Z2,Parámetros!$A$27:$A$31,0)))) | V2: Crane fórm. 6 (θ = 180°): contracción y expansión en el inserto | W2: 1.95 | X2: https://latiendadeljardin.com/es/piezas-de-polietileno/443-663-manguito-igual-pe.html | Z2: MANG | AA2: PE | AB2: =IF(COUNTIFS(Packs!$D$2:$D$70,A2,Packs!$F$2:$F$70,">0")=0,"",_xlfn.MINIFS(Packs!$F$2:$F$70,Packs!$D$2:$D$70,A2,Packs!$F$2:$F$70,">0")) -> 3.2375 | AC2: =COUNTIF(Packs!$D$2:$D$70,A2) -> 1
A3: PE-MI-25 | B3: Manguito igual PE | C3: 5220 | D3: manguito | E3: Manguito de compresión igual | F3: Compresión × compresión | G3: 25 | J3: 16 | K3: PP (cuerpo) · compresión para tubo PE | L3: =INDEX(Parámetros!$D$5:$D$12,MATCH(G3,Parámetros!$A$5:$A$12,0)) -> 20.4 | M3: =INDEX(Parámetros!$D$5:$D$12,MATCH(IF(H3="",G3,H3),Parámetros!$A$5:$A$12,0)) -> 20.4 | N3: =INDEX(Parámetros!$E$5:$E$12,MATCH(G3,Parámetros!$A$5:$A$12,0)) -> 17 | P3: =INDEX(Parámetros!$G$5:$G$12,MATCH(G3,Parámetros!$A$5:$A$12,0)) -> 0.025 | Q3: =IF(Z3="","",INDEX(Parámetros!$C$27:$C$31,MATCH(Z3,Parámetros!$A$27:$A$31,0))*P3) -> 0 | S3: =(Q3+0.5*(1-(N3/L3)^2)+(1-(N3/M3)^2)^2)*(M3/N3)^4+IF(Z3="",0,INDEX(Parámetros!$E$27:$E$31,MATCH(Z3,Parámetros!$A$27:$A$31,0))) -> 0.5104 | U3: =IF(H3="","",(Q3+0.5*(1-(N3/M3)^2)+(1-(N3/L3)^2)^2)*(M3/N3)^4+IF(Z3="",0,INDEX(Parámetros!$E$27:$E$31,MATCH(Z3,Parámetros!$A$27:$A$31,0)))) | V3: Crane fórm. 6 (θ = 180°): contracción y expansión en el inserto | W3: 1.95 | X3: https://latiendadeljardin.com/es/piezas-de-polietileno/443-663-manguito-igual-pe.html | Z3: MANG | AA3: PE | AB3: =IF(COUNTIFS(Packs!$D$2:$D$70,A3,Packs!$F$2:$F$70,">0")=0,"",_xlfn.MINIFS(Packs!$F$2:$F$70,Packs!$D$2:$D$70,A3,Packs!$F$2:$F$70,">0")) -> 2.9875 | AC3: =COUNTIF(Packs!$D$2:$D$70,A3) -> 1
A4: PE-MI-32 | B4: Manguito igual PE | C4: 5220 | D4: manguito | E4: Manguito de compresión igual | F4: Compresión × compresión | G4: 32 | J4: 16 | K4: PP (cuerpo) · compresión para tubo PE | L4: =INDEX(Parámetros!$D$5:$D$12,MATCH(G4,Parámetros!$A$5:$A$12,0)) -> 26.2 | M4: =INDEX(Parámetros!$D$5:$D$12,MATCH(IF(H4="",G4,H4),Parámetros!$A$5:$A$12,0)) -> 26.2 | N4: =INDEX(Parámetros!$E$5:$E$12,MATCH(G4,Parámetros!$A$5:$A$12,0)) -> 22 | P4: =INDEX(Parámetros!$G$5:$G$12,MATCH(G4,Parámetros!$A$5:$A$12,0)) -> 0.023 | Q4: =IF(Z4="","",INDEX(Parámetros!$C$27:$C$31,MATCH(Z4,Parámetros!$A$27:$A$31,0))*P4) -> 0 | S4: =(Q4+0.5*(1-(N4/L4)^2)+(1-(N4/M4)^2)^2)*(M4/N4)^4+IF(Z4="",0,INDEX(Parámetros!$E$27:$E$31,MATCH(Z4,Parámetros!$A$27:$A$31,0))) -> 0.47154997 | U4: =IF(H4="","",(Q4+0.5*(1-(N4/M4)^2)+(1-(N4/L4)^2)^2)*(M4/N4)^4+IF(Z4="",0,INDEX(Parámetros!$E$27:$E$31,MATCH(Z4,Parámetros!$A$27:$A$31,0)))) | V4: Crane fórm. 6 (θ = 180°): contracción y expansión en el inserto | W4: 1.95 | X4: https://latiendadeljardin.com/es/piezas-de-polietileno/443-663-manguito-igual-pe.html | Z4: MANG | AA4: PE | AB4: =IF(COUNTIFS(Packs!$D$2:$D$70,A4,Packs!$F$2:$F$70,">0")=0,"",_xlfn.MINIFS(Packs!$F$2:$F$70,Packs!$D$2:$D$70,A4,Packs!$F$2:$F$70,">0")) -> 3.7375 | AC4: =COUNTIF(Packs!$D$2:$D$70,A4) -> 1
A5: PE-MI-40 | B5: Manguito igual PE | C5: 5220 | D5: manguito | E5: Manguito de compresión igual | F5: Compresión × compresión | G5: 40 | J5: 16 | K5: PP (cuerpo) · compresión para tubo PE | L5: =INDEX(Parámetros!$D$5:$D$12,MATCH(G5,Parámetros!$A$5:$A$12,0)) -> 32.6 | M5: =INDEX(Parámetros!$D$5:$D$12,MATCH(IF(H5="",G5,H5),Parámetros!$A$5:$A$12,0)) -> 32.6 | N5: =INDEX(Parámetros!$E$5:$E$12,MATCH(G5,Parámetros!$A$5:$A$12,0)) -> 28 | P5: =INDEX(Parámetros!$G$5:$G$12,MATCH(G5,Parámetros!$A$5:$A$12,0)) -> 0.022 | Q5: =IF(Z5="","",INDEX(Parámetros!$C$27:$C$31,MATCH(Z5,Parámetros!$A$27:$A$31,0))*P5) -> 0 | S5: =(Q5+0.5*(1-(N5/L5)^2)+(1-(N5/M5)^2)^2)*(M5/N5)^4+IF(Z5="",0,INDEX(Parámetros!$E$27:$E$31,MATCH(Z5,Parámetros!$A$27:$A$31,0))) -> 0.36741629 | U5: =IF(H5="","",(Q5+0.5*(1-(N5/M5)^2)+(1-(N5/L5)^2)^2)*(M5/N5)^4+IF(Z5="",0,INDEX(Parámetros!$E$27:$E$31,MATCH(Z5,Parámetros!$A$27:$A$31,0)))) | V5: Crane fórm. 6 (θ = 180°): contracción y expansión en el inserto | W5: 1.95 | X5: https://latiendadeljardin.com/es/piezas-de-polietileno/443-663-manguito-igual-pe.html | Z5: MANG | AA5: PE | AB5: =IF(COUNTIFS(Packs!$D$2:$D$70,A5,Packs!$F$2:$F$70,">0")=0,"",_xlfn.MINIFS(Packs!$F$2:$F$70,Packs!$D$2:$D$70,A5,Packs!$F$2:$F$70,">0")) -> 6.2375 | AC5: =COUNTIF(Packs!$D$2:$D$70,A5) -> 1
A6: PE-MI-50 | B6: Manguito igual PE | C6: 5220 | D6: manguito | E6: Manguito de compresión igual | F6: Compresión × compresión | G6: 50 | J6: 16 | K6: PP (cuerpo) · compresión para tubo PE | L6: =INDEX(Parámetros!$D$5:$D$12,MATCH(G6,Parámetros!$A$5:$A$12,0)) -> 40.8 | M6: =INDEX(Parámetros!$D$5:$D$12,MATCH(IF(H6="",G6,H6),Parámetros!$A$5:$A$12,0)) -> 40.8 | N6: =INDEX(Parámetros!$E$5:$E$12,MATCH(G6,Parámetros!$A$5:$A$12,0)) -> 35 | P6: =INDEX(Parámetros!$G$5:$G$12,MATCH(G6,Parámetros!$A$5:$A$12,0)) -> 0.021 | Q6: =IF(Z6="","",INDEX(Parámetros!$C$27:$C$31,MATCH(Z6,Parámetros!$A$27:$A$31,0))*P6) -> 0 | S6: =(Q6+0.5*(1-(N6/L6)^2)+(1-(N6/M6)^2)^2)*(M6/N6)^4+IF(Z6="",0,INDEX(Parámetros!$E$27:$E$31,MATCH(Z6,Parámetros!$A$27:$A$31,0))) -> 0.37264773 | U6: =IF(H6="","",(Q6+0.5*(1-(N6/M6)^2)+(1-(N6/L6)^2)^2)*(M6/N6)^4+IF(Z6="",0,INDEX(Parámetros!$E$27:$E$31,MATCH(Z6,Parámetros!$A$27:$A$31,0)))) | V6: Crane fórm. 6 (θ = 180°): contracción y expansión en el inserto | W6: 1.95 | X6: https://latiendadeljardin.com/es/piezas-de-polietileno/443-663-manguito-igual-pe.html | Z6: MANG | AA6: PE | AB6: =IF(COUNTIFS(Packs!$D$2:$D$70,A6,Packs!$F$2:$F$70,">0")=0,"",_xlfn.MINIFS(Packs!$F$2:$F$70,Packs!$D$2:$D$70,A6,Packs!$F$2:$F$70,">0")) -> 9.4875 | AC6: =COUNTIF(Packs!$D$2:$D$70,A6) -> 1
A7: PE-MI-63 | B7: Manguito igual PE | C7: 5220 | D7: manguito | E7: Manguito de compresión igual | F7: Compresión × compresión | G7: 63 | J7: 16 | K7: PP (cuerpo) · compresión para tubo PE | L7: =INDEX(Parámetros!$D$5:$D$12,MATCH(G7,Parámetros!$A$5:$A$12,0)) -> 51.4 | M7: =INDEX(Parámetros!$D$5:$D$12,MATCH(IF(H7="",G7,H7),Parámetros!$A$5:$A$12,0)) -> 51.4 | N7: =INDEX(Parámetros!$E$5:$E$12,MATCH(G7,Parámetros!$A$5:$A$12,0)) -> 45 | P7: =INDEX(Parámetros!$G$5:$G$12,MATCH(G7,Parámetros!$A$5:$A$12,0)) -> 0.019 | Q7: =IF(Z7="","",INDEX(Parámetros!$C$27:$C$31,MATCH(Z7,Parámetros!$A$27:$A$31,0))*P7) -> 0 | S7: =(Q7+0.5*(1-(N7/L7)^2)+(1-(N7/M7)^2)^2)*(M7/N7)^4+IF(Z7="",0,INDEX(Parámetros!$E$27:$E$31,MATCH(Z7,Parámetros!$A$27:$A$31,0))) -> 0.29157298 | U7: =IF(H7="","",(Q7+0.5*(1-(N7/M7)^2)+(1-(N7/L7)^2)^2)*(M7/N7)^4+IF(Z7="",0,INDEX(Parámetros!$E$27:$E$31,MATCH(Z7,Parámetros!$A$27:$A$31,0)))) | V7: Crane fórm. 6 (θ = 180°): contracción y expansión en el inserto | W7: 1.95 | X7: https://latiendadeljardin.com/es/piezas-de-polietileno/443-663-manguito-igual-pe.html | Z7: MANG | AA7: PE | AB7: =IF(COUNTIFS(Packs!$D$2:$D$70,A7,Packs!$F$2:$F$70,">0")=0,"",_xlfn.MINIFS(Packs!$F$2:$F$70,Packs!$D$2:$D$70,A7,Packs!$F$2:$F$70,">0")) -> 14.7375 | AC7: =COUNTIF(Packs!$D$2:$D$70,A7) -> 1
A8: PE-MI-75 | B8: Manguito igual PE | C8: 5220 | D8: manguito | E8: Manguito de compresión igual | F8: Compresión × compresión | G8: 75 | J8: 16 | K8: PP (cuerpo) · compresión para tubo PE | L8: =INDEX(Parámetros!$D$5:$D$12,MATCH(G8,Parámetros!$A$5:$A$12,0)) -> 61.4 | M8: =INDEX(Parámetros!$D$5:$D$12,MATCH(IF(H8="",G8,H8),Parámetros!$A$5:$A$12,0)) -> 61.4 | N8: =INDEX(Parámetros!$E$5:$E$12,MATCH(G8,Parámetros!$A$5:$A$12,0)) -> 54 | P8: =INDEX(Parámetros!$G$5:$G$12,MATCH(G8,Parámetros!$A$5:$A$12,0)) -> 0.018 | Q8: =IF(Z8="","",INDEX(Parámetros!$C$27:$C$31,MATCH(Z8,Parámetros!$A$27:$A$31,0))*P8) -> 0 | S8: =(Q8+0.5*(1-(N8/L8)^2)+(1-(N8/M8)^2)^2)*(M8/N8)^4+IF(Z8="",0,INDEX(Parámetros!$E$27:$E$31,MATCH(Z8,Parámetros!$A$27:$A$31,0))) -> 0.27507113 | U8: =IF(H8="","",(Q8+0.5*(1-(N8/M8)^2)+(1-(N8/L8)^2)^2)*(M8/N8)^4+IF(Z8="",0,INDEX(Parámetros!$E$27:$E$31,MATCH(Z8,Parámetros!$A$27:$A$31,0)))) | V8: Crane fórm. 6 (θ = 180°): contracción y expansión en el inserto | W8: 1.95 | X8: https://latiendadeljardin.com/es/piezas-de-polietileno/443-663-manguito-igual-pe.html | Z8: MANG | AA8: PE | AB8: =IF(COUNTIFS(Packs!$D$2:$D$70,A8,Packs!$F$2:$F$70,">0")=0,"",_xlfn.MINIFS(Packs!$F$2:$F$70,Packs!$D$2:$D$70,A8,Packs!$F$2:$F$70,">0")) -> 17.79 | AC8: =COUNTIF(Packs!$D$2:$D$70,A8) -> 1
A9: PE-MI-90 | B9: Manguito igual PE | C9: 5220 | D9: manguito | E9: Manguito de compresión igual | F9: Compresión × compresión | G9: 90 | J9: 16 | K9: PP (cuerpo) · compresión para tubo PE | L9: =INDEX(Parámetros!$D$5:$D$12,MATCH(G9,Parámetros!$A$5:$A$12,0)) -> 73.6 | M9: =INDEX(Parámetros!$D$5:$D$12,MATCH(IF(H9="",G9,H9),Parámetros!$A$5:$A$12,0)) -> 73.6 | N9: =INDEX(Parámetros!$E$5:$E$12,MATCH(G9,Parámetros!$A$5:$A$12,0)) -> 66 | P9: =INDEX(Parámetros!$G$5:$G$12,MATCH(G9,Parámetros!$A$5:$A$12,0)) -> 0.018 | Q9: =IF(Z9="","",INDEX(Parámetros!$C$27:$C$31,MATCH(Z9,Parámetros!$A$27:$A$31,0))*P9) -> 0 | S9: =(Q9+0.5*(1-(N9/L9)^2)+(1-(N9/M9)^2)^2)*(M9/N9)^4+IF(Z9="",0,INDEX(Parámetros!$E$27:$E$31,MATCH(Z9,Parámetros!$A$27:$A$31,0))) -> 0.21076578 | U9: =IF(H9="","",(Q9+0.5*(1-(N9/M9)^2)+(1-(N9/L9)^2)^2)*(M9/N9)^4+IF(Z9="",0,INDEX(Parámetros!$E$27:$E$31,MATCH(Z9,Parámetros!$A$27:$A$31,0)))) | V9: Crane fórm. 6 (θ = 180°): contracción y expansión en el inserto | W9: 1.95 | X9: https://latiendadeljardin.com/es/piezas-de-polietileno/443-663-manguito-igual-pe.html | Z9: MANG | AA9: PE | AB9: =IF(COUNTIFS(Packs!$D$2:$D$70,A9,Packs!$F$2:$F$70,">0")=0,"",_xlfn.MINIFS(Packs!$F$2:$F$70,Packs!$D$2:$D$70,A9,Packs!$F$2:$F$70,">0")) -> 26.19 | AC9: =COUNTIF(Packs!$D$2:$D$70,A9) -> 1
A10: PE-MR-25x20 | B10: Manguito reducido PE | C10: 5325 | D10: reduccion | E10: Manguito reducido de compresión (concéntrico) | F10: Compresión × compresión | G10: 25 | H10: 20 | J10: 16 | K10: PP (cuerpo) · compresión para tubo PE | L10: =INDEX(Parámetros!$D$5:$D$12,MATCH(G10,Parámetros!$A$5:$A$12,0)) -> 20.4 | M10: =INDEX(Parámetros!$D$5:$D$12,MATCH(IF(H10="",G10,H10),Parámetros!$A$5:$A$12,0)) -> 16 | N10: =INDEX(Parámetros!$E$5:$E$12,MATCH(IF(H10="",G10,H10),Parámetros!$A$5:$A$12,0)) -> 13 | P10: =INDEX(Parámetros!$G$5:$G$12,MATCH(G10,Parámetros!$A$5:$A$12,0)) -> 0.025 | Q10: =IF(Z10="","",INDEX(Parámetros!$C$27:$C$31,MATCH(Z10,Parámetros!$A$27:$A$31,0))*P10) -> 0 | S10: =(Q10+0.5*(1-(N10/L10)^2)+(1-(N10/M10)^2)^2)*(M10/N10)^4+IF(Z10="",0,INDEX(Parámetros!$E$27:$E$31,MATCH(Z10,Parámetros!$A$27:$A$31,0))) -> 0.94639957 | U10: =IF(H10="","",(Q10+0.5*(1-(N10/M10)^2)+(1-(N10/L10)^2)^2)*(M10/N10)^4+IF(Z10="",0,INDEX(Parámetros!$E$27:$E$31,MATCH(Z10,Parámetros!$A$27:$A$31,0)))) -> 1.1992632 | V10: Crane fórm. 6 (θ = 180°): contracción y expansión en el inserto; reducida: contracción desde la medida mayor | W10: 2.29 | X10: https://latiendadeljardin.com/es/piezas-de-polietileno/444-679-manguito-reducido-pe.html | Z10: MANG | AA10: PE | AB10: =IF(COUNTIFS(Packs!$D$2:$D$70,A10,Packs!$F$2:$F$70,">0")=0,"",_xlfn.MINIFS(Packs!$F$2:$F$70,Packs!$D$2:$D$70,A10,Packs!$F$2:$F$70,">0")) -> 2.4875 | AC10: =COUNTIF(Packs!$D$2:$D$70,A10) -> 1
A11: PE-MR-32x25 | B11: Manguito reducido PE | C11: 5325 | D11: reduccion | E11: Manguito reducido de compresión (concéntrico) | F11: Compresión × compresión | G11: 32 | H11: 25 | J11: 16 | K11: PP (cuerpo) · compresión para tubo PE | L11: =INDEX(Parámetros!$D$5:$D$12,MATCH(G11,Parámetros!$A$5:$A$12,0)) -> 26.2 | M11: =INDEX(Parámetros!$D$5:$D$12,MATCH(IF(H11="",G11,H11),Parámetros!$A$5:$A$12,0)) -> 20.4 | N11: =INDEX(Parámetros!$E$5:$E$12,MATCH(IF(H11="",G11,H11),Parámetros!$A$5:$A$12,0)) -> 17 | P11: =INDEX(Parámetros!$G$5:$G$12,MATCH(G11,Parámetros!$A$5:$A$12,0)) -> 0.023 | Q11: =IF(Z11="","",INDEX(Parámetros!$C$27:$C$31,MATCH(Z11,Parámetros!$A$27:$A$31,0))*P11) -> 0 | S11: =(Q11+0.5*(1-(N11/L11)^2)+(1-(N11/M11)^2)^2)*(M11/N11)^4+IF(Z11="",0,INDEX(Parámetros!$E$27:$E$31,MATCH(Z11,Parámetros!$A$27:$A$31,0))) -> 0.79389397 | U11: =IF(H11="","",(Q11+0.5*(1-(N11/M11)^2)+(1-(N11/L11)^2)^2)*(M11/N11)^4+IF(Z11="",0,INDEX(Parámetros!$E$27:$E$31,MATCH(Z11,Parámetros!$A$27:$A$31,0)))) -> 1.0119251 | V11: Crane fórm. 6 (θ = 180°): contracción y expansión en el inserto; reducida: contracción desde la medida mayor | W11: 2.29 | X11: https://latiendadeljardin.com/es/piezas-de-polietileno/444-679-manguito-reducido-pe.html | Z11: MANG | AA11: PE | AB11: =IF(COUNTIFS(Packs!$D$2:$D$70,A11,Packs!$F$2:$F$70,">0")=0,"",_xlfn.MINIFS(Packs!$F$2:$F$70,Packs!$D$2:$D$70,A11,Packs!$F$2:$F$70,">0")) -> 3.2375 | AC11: =COUNTIF(Packs!$D$2:$D$70,A11) -> 1
A12: PE-MR-40x32 | B12: Manguito reducido PE | C12: 5325 | D12: reduccion | E12: Manguito reducido de compresión (concéntrico) | F12: Compresión × compresión | G12: 40 | H12: 32 | J12: 16 | K12: PP (cuerpo) · compresión para tubo PE | L12: =INDEX(Parámetros!$D$5:$D$12,MATCH(G12,Parámetros!$A$5:$A$12,0)) -> 32.6 | M12: =INDEX(Parámetros!$D$5:$D$12,MATCH(IF(H12="",G12,H12),Parámetros!$A$5:$A$12,0)) -> 26.2 | N12: =INDEX(Parámetros!$E$5:$E$12,MATCH(IF(H12="",G12,H12),Parámetros!$A$5:$A$12,0)) -> 22 | P12: =INDEX(Parámetros!$G$5:$G$12,MATCH(G12,Parámetros!$A$5:$A$12,0)) -> 0.022 | Q12: =IF(Z12="","",INDEX(Parámetros!$C$27:$C$31,MATCH(Z12,Parámetros!$A$27:$A$31,0))*P12) -> 0 | S12: =(Q12+0.5*(1-(N12/L12)^2)+(1-(N12/M12)^2)^2)*(M12/N12)^4+IF(Z12="",0,INDEX(Parámetros!$E$27:$E$31,MATCH(Z12,Parámetros!$A$27:$A$31,0))) -> 0.72265148 | U12: =IF(H12="","",(Q12+0.5*(1-(N12/M12)^2)+(1-(N12/L12)^2)^2)*(M12/N12)^4+IF(Z12="",0,INDEX(Parámetros!$E$27:$E$31,MATCH(Z12,Parámetros!$A$27:$A$31,0)))) -> 0.89314686 | V12: Crane fórm. 6 (θ = 180°): contracción y expansión en el inserto; reducida: contracción desde la medida mayor | W12: 2.29 | X12: https://latiendadeljardin.com/es/piezas-de-polietileno/444-679-manguito-reducido-pe.html | Z12: MANG | AA12: PE | AB12: =IF(COUNTIFS(Packs!$D$2:$D$70,A12,Packs!$F$2:$F$70,">0")=0,"",_xlfn.MINIFS(Packs!$F$2:$F$70,Packs!$D$2:$D$70,A12,Packs!$F$2:$F$70,">0")) -> 4.7375 | AC12: =COUNTIF(Packs!$D$2:$D$70,A12) -> 1
A13: PE-MR-50x40 | B13: Manguito reducido PE | C13: 5325 | D13: reduccion | E13: Manguito reducido de compresión (concéntrico) | F13: Compresión × compresión | G13: 50 | H13: 40 | J13: 16 | K13: PP (cuerpo) · compresión para tubo PE | L13: =INDEX(Parámetros!$D$5:$D$12,MATCH(G13,Parámetros!$A$5:$A$12,0)) -> 40.8 | M13: =INDEX(Parámetros!$D$5:$D$12,MATCH(IF(H13="",G13,H13),Parámetros!$A$5:$A$12,0)) -> 32.6 | N13: =INDEX(Parámetros!$E$5:$E$12,MATCH(IF(H13="",G13,H13),Parámetros!$A$5:$A$12,0)) -> 28 | P13: =INDEX(Parámetros!$G$5:$G$12,MATCH(G13,Parámetros!$A$5:$A$12,0)) -> 0.021 | Q13: =IF(Z13="","",INDEX(Parámetros!$C$27:$C$31,MATCH(Z13,Parámetros!$A$27:$A$31,0))*P13) -> 0 | S13: =(Q13+0.5*(1-(N13/L13)^2)+(1-(N13/M13)^2)^2)*(M13/N13)^4+IF(Z13="",0,INDEX(Parámetros!$E$27:$E$31,MATCH(Z13,Parámetros!$A$27:$A$31,0))) -> 0.61247984 | U13: =IF(H13="","",(Q13+0.5*(1-(N13/M13)^2)+(1-(N13/L13)^2)^2)*(M13/N13)^4+IF(Z13="",0,INDEX(Parámetros!$E$27:$E$31,MATCH(Z13,Parámetros!$A$27:$A$31,0)))) -> 0.75526635 | V13: Crane fórm. 6 (θ = 180°): contracción y expansión en el inserto; reducida: contracción desde la medida mayor | W13: 2.29 | X13: https://latiendadeljardin.com/es/piezas-de-polietileno/444-679-manguito-reducido-pe.html | Z13: MANG | AA13: PE | AB13: =IF(COUNTIFS(Packs!$D$2:$D$70,A13,Packs!$F$2:$F$70,">0")=0,"",_xlfn.MINIFS(Packs!$F$2:$F$70,Packs!$D$2:$D$70,A13,Packs!$F$2:$F$70,">0")) -> 6.7375 | AC13: =COUNTIF(Packs!$D$2:$D$70,A13) -> 1
A14: PE-MR-63x50 | B14: Manguito reducido PE | C14: 5325 | D14: reduccion | E14: Manguito reducido de compresión (concéntrico) | F14: Compresión × compresión | G14: 63 | H14: 50 | J14: 16 | K14: PP (cuerpo) · compresión para tubo PE | L14: =INDEX(Parámetros!$D$5:$D$12,MATCH(G14,Parámetros!$A$5:$A$12,0)) -> 51.4 | M14: =INDEX(Parámetros!$D$5:$D$12,MATCH(IF(H14="",G14,H14),Parámetros!$A$5:$A$12,0)) -> 40.8 | N14: =INDEX(Parámetros!$E$5:$E$12,MATCH(IF(H14="",G14,H14),Parámetros!$A$5:$A$12,0)) -> 35 | P14: =INDEX(Parámetros!$G$5:$G$12,MATCH(G14,Parámetros!$A$5:$A$12,0)) -> 0.019 | Q14: =IF(Z14="","",INDEX(Parámetros!$C$27:$C$31,MATCH(Z14,Parámetros!$A$27:$A$31,0))*P14) -> 0 | S14: =(Q14+0.5*(1-(N14/L14)^2)+(1-(N14/M14)^2)^2)*(M14/N14)^4+IF(Z14="",0,INDEX(Parámetros!$E$27:$E$31,MATCH(Z14,Parámetros!$A$27:$A$31,0))) -> 0.62398957 | U14: =IF(H14="","",(Q14+0.5*(1-(N14/M14)^2)+(1-(N14/L14)^2)^2)*(M14/N14)^4+IF(Z14="",0,INDEX(Parámetros!$E$27:$E$31,MATCH(Z14,Parámetros!$A$27:$A$31,0)))) -> 0.77501296 | V14: Crane fórm. 6 (θ = 180°): contracción y expansión en el inserto; reducida: contracción desde la medida mayor | W14: 2.29 | X14: https://latiendadeljardin.com/es/piezas-de-polietileno/444-679-manguito-reducido-pe.html | Z14: MANG | AA14: PE | AB14: =IF(COUNTIFS(Packs!$D$2:$D$70,A14,Packs!$F$2:$F$70,">0")=0,"",_xlfn.MINIFS(Packs!$F$2:$F$70,Packs!$D$2:$D$70,A14,Packs!$F$2:$F$70,">0")) -> 10.2375 | AC14: =COUNTIF(Packs!$D$2:$D$70,A14) -> 1
A15: PE-MR-75x63 | B15: Manguito reducido PE | C15: 5325 | D15: reduccion | E15: Manguito reducido de compresión (concéntrico) | F15: Compresión × compresión | G15: 75 | H15: 63 | J15: 16 | K15: PP (cuerpo) · compresión para tubo PE | L15: =INDEX(Parámetros!$D$5:$D$12,MATCH(G15,Parámetros!$A$5:$A$12,0)) -> 61.4 | M15: =INDEX(Parámetros!$D$5:$D$12,MATCH(IF(H15="",G15,H15),Parámetros!$A$5:$A$12,0)) -> 51.4 | N15: =INDEX(Parámetros!$E$5:$E$12,MATCH(IF(H15="",G15,H15),Parámetros!$A$5:$A$12,0)) -> 45 | P15: =INDEX(Parámetros!$G$5:$G$12,MATCH(G15,Parámetros!$A$5:$A$12,0)) -> 0.018 | Q15: =IF(Z15="","",INDEX(Parámetros!$C$27:$C$31,MATCH(Z15,Parámetros!$A$27:$A$31,0))*P15) -> 0 | S15: =(Q15+0.5*(1-(N15/L15)^2)+(1-(N15/M15)^2)^2)*(M15/N15)^4+IF(Z15="",0,INDEX(Parámetros!$E$27:$E$31,MATCH(Z15,Parámetros!$A$27:$A$31,0))) -> 0.48675669 | U15: =IF(H15="","",(Q15+0.5*(1-(N15/M15)^2)+(1-(N15/L15)^2)^2)*(M15/N15)^4+IF(Z15="",0,INDEX(Parámetros!$E$27:$E$31,MATCH(Z15,Parámetros!$A$27:$A$31,0)))) -> 0.56341807 | V15: Crane fórm. 6 (θ = 180°): contracción y expansión en el inserto; reducida: contracción desde la medida mayor | W15: 2.29 | X15: https://latiendadeljardin.com/es/piezas-de-polietileno/444-679-manguito-reducido-pe.html | Z15: MANG | AA15: PE | AB15: =IF(COUNTIFS(Packs!$D$2:$D$70,A15,Packs!$F$2:$F$70,">0")=0,"",_xlfn.MINIFS(Packs!$F$2:$F$70,Packs!$D$2:$D$70,A15,Packs!$F$2:$F$70,">0")) -> 18.9875 | AC15: =COUNTIF(Packs!$D$2:$D$70,A15) -> 1
A16: PE-MR-90x75 | B16: Manguito reducido PE | C16: 5325 | D16: reduccion | E16: Manguito reducido de compresión (concéntrico) | F16: Compresión × compresión | G16: 90 | H16: 75 | J16: 16 | K16: PP (cuerpo) · compresión para tubo PE | L16: =INDEX(Parámetros!$D$5:$D$12,MATCH(G16,Parámetros!$A$5:$A$12,0)) -> 73.6 | M16: =INDEX(Parámetros!$D$5:$D$12,MATCH(IF(H16="",G16,H16),Parámetros!$A$5:$A$12,0)) -> 61.4 | N16: =INDEX(Parámetros!$E$5:$E$12,MATCH(IF(H16="",G16,H16),Parámetros!$A$5:$A$12,0)) -> 54 | P16: =INDEX(Parámetros!$G$5:$G$12,MATCH(G16,Parámetros!$A$5:$A$12,0)) -> 0.018 | Q16: =IF(Z16="","",INDEX(Parámetros!$C$27:$C$31,MATCH(Z16,Parámetros!$A$27:$A$31,0))*P16) -> 0 | S16: =(Q16+0.5*(1-(N16/L16)^2)+(1-(N16/M16)^2)^2)*(M16/N16)^4+IF(Z16="",0,INDEX(Parámetros!$E$27:$E$31,MATCH(Z16,Parámetros!$A$27:$A$31,0))) -> 0.47161395 | U16: =IF(H16="","",(Q16+0.5*(1-(N16/M16)^2)+(1-(N16/L16)^2)^2)*(M16/N16)^4+IF(Z16="",0,INDEX(Parámetros!$E$27:$E$31,MATCH(Z16,Parámetros!$A$27:$A$31,0)))) -> 0.54559569 | V16: Crane fórm. 6 (θ = 180°): contracción y expansión en el inserto; reducida: contracción desde la medida mayor | W16: 2.29 | X16: https://latiendadeljardin.com/es/piezas-de-polietileno/444-679-manguito-reducido-pe.html | Z16: MANG | AA16: PE | AB16: =IF(COUNTIFS(Packs!$D$2:$D$70,A16,Packs!$F$2:$F$70,">0")=0,"",_xlfn.MINIFS(Packs!$F$2:$F$70,Packs!$D$2:$D$70,A16,Packs!$F$2:$F$70,">0")) -> 27.4875 | AC16: =COUNTIF(Packs!$D$2:$D$70,A16) -> 1
A17: PE-EH-20 | B17: Enlace rosca hembra PE | C17: 5120 | D17: racor | E17: Enlace compresión × rosca hembra BSP | F17: Compresión × rosca H | G17: 20 | I17: 1/2" | J17: 16 | K17: PP (cuerpo) · compresión para tubo PE | L17: =INDEX(Parámetros!$D$5:$D$12,MATCH(G17,Parámetros!$A$5:$A$12,0)) -> 16 | M17: =INDEX(Parámetros!$D$5:$D$12,MATCH(IF(H17="",G17,H17),Parámetros!$A$5:$A$12,0)) -> 16 | N17: =INDEX(Parámetros!$E$5:$E$12,MATCH(G17,Parámetros!$A$5:$A$12,0)) -> 13 | P17: =INDEX(Parámetros!$G$5:$G$12,MATCH(G17,Parámetros!$A$5:$A$12,0)) -> 0.027 | Q17: =IF(Z17="","",INDEX(Parámetros!$C$27:$C$31,MATCH(Z17,Parámetros!$A$27:$A$31,0))*P17) -> 0 | S17: =(Q17+0.5*(1-(N17/L17)^2)+(1-(N17/M17)^2)^2)*(M17/N17)^4+IF(Z17="",0,INDEX(Parámetros!$E$27:$E$31,MATCH(Z17,Parámetros!$A$27:$A$31,0))) -> 0.65491404 | U17: =IF(H17="","",(Q17+0.5*(1-(N17/M17)^2)+(1-(N17/L17)^2)^2)*(M17/N17)^4+IF(Z17="",0,INDEX(Parámetros!$E$27:$E$31,MATCH(Z17,Parámetros!$A$27:$A$31,0)))) | V17: Crane fórm. 6 (θ = 180°): contracción y expansión en el inserto | W17: 1.55 | X17: https://latiendadeljardin.com/es/piezas-de-polietileno/445-693-enlace-hembra-pe.html | Y17: Rosca equivalente supuesta (la ficha no la indica) | Z17: MANG | AA17: PE | AB17: =IF(COUNTIFS(Packs!$D$2:$D$70,A17,Packs!$F$2:$F$70,">0")=0,"",_xlfn.MINIFS(Packs!$F$2:$F$70,Packs!$D$2:$D$70,A17,Packs!$F$2:$F$70,">0")) -> 1.4875 | AC17: =COUNTIF(Packs!$D$2:$D$70,A17) -> 1
A18: PE-EH-25 | B18: Enlace rosca hembra PE | C18: 5120 | D18: racor | E18: Enlace compresión × rosca hembra BSP | F18: Compresión × rosca H | G18: 25 | I18: 3/4" | J18: 16 | K18: PP (cuerpo) · compresión para tubo PE | L18: =INDEX(Parámetros!$D$5:$D$12,MATCH(G18,Parámetros!$A$5:$A$12,0)) -> 20.4 | M18: =INDEX(Parámetros!$D$5:$D$12,MATCH(IF(H18="",G18,H18),Parámetros!$A$5:$A$12,0)) -> 20.4 | N18: =INDEX(Parámetros!$E$5:$E$12,MATCH(G18,Parámetros!$A$5:$A$12,0)) -> 17 | P18: =INDEX(Parámetros!$G$5:$G$12,MATCH(G18,Parámetros!$A$5:$A$12,0)) -> 0.025 | Q18: =IF(Z18="","",INDEX(Parámetros!$C$27:$C$31,MATCH(Z18,Parámetros!$A$27:$A$31,0))*P18) -> 0 | S18: =(Q18+0.5*(1-(N18/L18)^2)+(1-(N18/M18)^2)^2)*(M18/N18)^4+IF(Z18="",0,INDEX(Parámetros!$E$27:$E$31,MATCH(Z18,Parámetros!$A$27:$A$31,0))) -> 0.5104 | U18: =IF(H18="","",(Q18+0.5*(1-(N18/M18)^2)+(1-(N18/L18)^2)^2)*(M18/N18)^4+IF(Z18="",0,INDEX(Parámetros!$E$27:$E$31,MATCH(Z18,Parámetros!$A$27:$A$31,0)))) | V18: Crane fórm. 6 (θ = 180°): contracción y expansión en el inserto | W18: 1.55 | X18: https://latiendadeljardin.com/es/piezas-de-polietileno/445-693-enlace-hembra-pe.html | Y18: Rosca equivalente supuesta (la ficha no la indica) | Z18: MANG | AA18: PE | AB18: =IF(COUNTIFS(Packs!$D$2:$D$70,A18,Packs!$F$2:$F$70,">0")=0,"",_xlfn.MINIFS(Packs!$F$2:$F$70,Packs!$D$2:$D$70,A18,Packs!$F$2:$F$70,">0")) -> 1.9875 | AC18: =COUNTIF(Packs!$D$2:$D$70,A18) -> 1
A19: PE-EH-32 | B19: Enlace rosca hembra PE | C19: 5120 | D19: racor | E19: Enlace compresión × rosca hembra BSP | F19: Compresión × rosca H | G19: 32 | I19: 1" | J19: 16 | K19: PP (cuerpo) · compresión para tubo PE | L19: =INDEX(Parámetros!$D$5:$D$12,MATCH(G19,Parámetros!$A$5:$A$12,0)) -> 26.2 | M19: =INDEX(Parámetros!$D$5:$D$12,MATCH(IF(H19="",G19,H19),Parámetros!$A$5:$A$12,0)) -> 26.2 | N19: =INDEX(Parámetros!$E$5:$E$12,MATCH(G19,Parámetros!$A$5:$A$12,0)) -> 22 | P19: =INDEX(Parámetros!$G$5:$G$12,MATCH(G19,Parámetros!$A$5:$A$12,0)) -> 0.023 | Q19: =IF(Z19="","",INDEX(Parámetros!$C$27:$C$31,MATCH(Z19,Parámetros!$A$27:$A$31,0))*P19) -> 0 | S19: =(Q19+0.5*(1-(N19/L19)^2)+(1-(N19/M19)^2)^2)*(M19/N19)^4+IF(Z19="",0,INDEX(Parámetros!$E$27:$E$31,MATCH(Z19,Parámetros!$A$27:$A$31,0))) -> 0.47154997 | U19: =IF(H19="","",(Q19+0.5*(1-(N19/M19)^2)+(1-(N19/L19)^2)^2)*(M19/N19)^4+IF(Z19="",0,INDEX(Parámetros!$E$27:$E$31,MATCH(Z19,Parámetros!$A$27:$A$31,0)))) | V19: Crane fórm. 6 (θ = 180°): contracción y expansión en el inserto | W19: 1.55 | X19: https://latiendadeljardin.com/es/piezas-de-polietileno/445-693-enlace-hembra-pe.html | Y19: Rosca equivalente supuesta (la ficha no la indica) | Z19: MANG | AA19: PE | AB19: =IF(COUNTIFS(Packs!$D$2:$D$70,A19,Packs!$F$2:$F$70,">0")=0,"",_xlfn.MINIFS(Packs!$F$2:$F$70,Packs!$D$2:$D$70,A19,Packs!$F$2:$F$70,">0")) -> 2.7375 | AC19: =COUNTIF(Packs!$D$2:$D$70,A19) -> 1
A20: PE-EH-40 | B20: Enlace rosca hembra PE | C20: 5120 | D20: racor | E20: Enlace compresión × rosca hembra BSP | F20: Compresión × rosca H | G20: 40 | I20: 1 1/4" | J20: 16 | K20: PP (cuerpo) · compresión para tubo PE | L20: =INDEX(Parámetros!$D$5:$D$12,MATCH(G20,Parámetros!$A$5:$A$12,0)) -> 32.6 | M20: =INDEX(Parámetros!$D$5:$D$12,MATCH(IF(H20="",G20,H20),Parámetros!$A$5:$A$12,0)) -> 32.6 | N20: =INDEX(Parámetros!$E$5:$E$12,MATCH(G20,Parámetros!$A$5:$A$12,0)) -> 28 | P20: =INDEX(Parámetros!$G$5:$G$12,MATCH(G20,Parámetros!$A$5:$A$12,0)) -> 0.022 | Q20: =IF(Z20="","",INDEX(Parámetros!$C$27:$C$31,MATCH(Z20,Parámetros!$A$27:$A$31,0))*P20) -> 0 | S20: =(Q20+0.5*(1-(N20/L20)^2)+(1-(N20/M20)^2)^2)*(M20/N20)^4+IF(Z20="",0,INDEX(Parámetros!$E$27:$E$31,MATCH(Z20,Parámetros!$A$27:$A$31,0))) -> 0.36741629 | U20: =IF(H20="","",(Q20+0.5*(1-(N20/M20)^2)+(1-(N20/L20)^2)^2)*(M20/N20)^4+IF(Z20="",0,INDEX(Parámetros!$E$27:$E$31,MATCH(Z20,Parámetros!$A$27:$A$31,0)))) | V20: Crane fórm. 6 (θ = 180°): contracción y expansión en el inserto | W20: 1.55 | X20: https://latiendadeljardin.com/es/piezas-de-polietileno/445-693-enlace-hembra-pe.html | Y20: Rosca equivalente supuesta (la ficha no la indica) | Z20: MANG | AA20: PE | AB20: =IF(COUNTIFS(Packs!$D$2:$D$70,A20,Packs!$F$2:$F$70,">0")=0,"",_xlfn.MINIFS(Packs!$F$2:$F$70,Packs!$D$2:$D$70,A20,Packs!$F$2:$F$70,">0")) -> 3.9875 | AC20: =COUNTIF(Packs!$D$2:$D$70,A20) -> 1
A21: PE-EH-50 | B21: Enlace rosca hembra PE | C21: 5120 | D21: racor | E21: Enlace compresión × rosca hembra BSP | F21: Compresión × rosca H | G21: 50 | I21: 1 1/2" | J21: 16 | K21: PP (cuerpo) · compresión para tubo PE | L21: =INDEX(Parámetros!$D$5:$D$12,MATCH(G21,Parámetros!$A$5:$A$12,0)) -> 40.8 | M21: =INDEX(Parámetros!$D$5:$D$12,MATCH(IF(H21="",G21,H21),Parámetros!$A$5:$A$12,0)) -> 40.8 | N21: =INDEX(Parámetros!$E$5:$E$12,MATCH(G21,Parámetros!$A$5:$A$12,0)) -> 35 | P21: =INDEX(Parámetros!$G$5:$G$12,MATCH(G21,Parámetros!$A$5:$A$12,0)) -> 0.021 | Q21: =IF(Z21="","",INDEX(Parámetros!$C$27:$C$31,MATCH(Z21,Parámetros!$A$27:$A$31,0))*P21) -> 0 | S21: =(Q21+0.5*(1-(N21/L21)^2)+(1-(N21/M21)^2)^2)*(M21/N21)^4+IF(Z21="",0,INDEX(Parámetros!$E$27:$E$31,MATCH(Z21,Parámetros!$A$27:$A$31,0))) -> 0.37264773 | U21: =IF(H21="","",(Q21+0.5*(1-(N21/M21)^2)+(1-(N21/L21)^2)^2)*(M21/N21)^4+IF(Z21="",0,INDEX(Parámetros!$E$27:$E$31,MATCH(Z21,Parámetros!$A$27:$A$31,0)))) | V21: Crane fórm. 6 (θ = 180°): contracción y expansión en el inserto | W21: 1.55 | X21: https://latiendadeljardin.com/es/piezas-de-polietileno/445-693-enlace-hembra-pe.html | Y21: Rosca equivalente supuesta (la ficha no la indica) | Z21: MANG | AA21: PE | AB21: =IF(COUNTIFS(Packs!$D$2:$D$70,A21,Packs!$F$2:$F$70,">0")=0,"",_xlfn.MINIFS(Packs!$F$2:$F$70,Packs!$D$2:$D$70,A21,Packs!$F$2:$F$70,">0")) -> 5.2375 | AC21: =COUNTIF(Packs!$D$2:$D$70,A21) -> 1
A22: PE-EH-63 | B22: Enlace rosca hembra PE | C22: 5120 | D22: racor | E22: Enlace compresión × rosca hembra BSP | F22: Compresión × rosca H | G22: 63 | I22: 2" | J22: 16 | K22: PP (cuerpo) · compresión para tubo PE | L22: =INDEX(Parámetros!$D$5:$D$12,MATCH(G22,Parámetros!$A$5:$A$12,0)) -> 51.4 | M22: =INDEX(Parámetros!$D$5:$D$12,MATCH(IF(H22="",G22,H22),Parámetros!$A$5:$A$12,0)) -> 51.4 | N22: =INDEX(Parámetros!$E$5:$E$12,MATCH(G22,Parámetros!$A$5:$A$12,0)) -> 45 | P22: =INDEX(Parámetros!$G$5:$G$12,MATCH(G22,Parámetros!$A$5:$A$12,0)) -> 0.019 | Q22: =IF(Z22="","",INDEX(Parámetros!$C$27:$C$31,MATCH(Z22,Parámetros!$A$27:$A$31,0))*P22) -> 0 | S22: =(Q22+0.5*(1-(N22/L22)^2)+(1-(N22/M22)^2)^2)*(M22/N22)^4+IF(Z22="",0,INDEX(Parámetros!$E$27:$E$31,MATCH(Z22,Parámetros!$A$27:$A$31,0))) -> 0.29157298 | U22: =IF(H22="","",(Q22+0.5*(1-(N22/M22)^2)+(1-(N22/L22)^2)^2)*(M22/N22)^4+IF(Z22="",0,INDEX(Parámetros!$E$27:$E$31,MATCH(Z22,Parámetros!$A$27:$A$31,0)))) | V22: Crane fórm. 6 (θ = 180°): contracción y expansión en el inserto | W22: 1.55 | X22: https://latiendadeljardin.com/es/piezas-de-polietileno/445-693-enlace-hembra-pe.html | Y22: Rosca equivalente supuesta (la ficha no la indica) | Z22: MANG | AA22: PE | AB22: =IF(COUNTIFS(Packs!$D$2:$D$70,A22,Packs!$F$2:$F$70,">0")=0,"",_xlfn.MINIFS(Packs!$F$2:$F$70,Packs!$D$2:$D$70,A22,Packs!$F$2:$F$70,">0")) -> 7.9875 | AC22: =COUNTIF(Packs!$D$2:$D$70,A22) -> 1
A23: PE-EH-75 | B23: Enlace rosca hembra PE | C23: 5120 | D23: racor | E23: Enlace compresión × rosca hembra BSP | F23: Compresión × rosca H | G23: 75 | I23: 2 1/2" | J23: 16 | K23: PP (cuerpo) · compresión para tubo PE | L23: =INDEX(Parámetros!$D$5:$D$12,MATCH(G23,Parámetros!$A$5:$A$12,0)) -> 61.4 | M23: =INDEX(Parámetros!$D$5:$D$12,MATCH(IF(H23="",G23,H23),Parámetros!$A$5:$A$12,0)) -> 61.4 | N23: =INDEX(Parámetros!$E$5:$E$12,MATCH(G23,Parámetros!$A$5:$A$12,0)) -> 54 | P23: =INDEX(Parámetros!$G$5:$G$12,MATCH(G23,Parámetros!$A$5:$A$12,0)) -> 0.018 | Q23: =IF(Z23="","",INDEX(Parámetros!$C$27:$C$31,MATCH(Z23,Parámetros!$A$27:$A$31,0))*P23) -> 0 | S23: =(Q23+0.5*(1-(N23/L23)^2)+(1-(N23/M23)^2)^2)*(M23/N23)^4+IF(Z23="",0,INDEX(Parámetros!$E$27:$E$31,MATCH(Z23,Parámetros!$A$27:$A$31,0))) -> 0.27507113 | U23: =IF(H23="","",(Q23+0.5*(1-(N23/M23)^2)+(1-(N23/L23)^2)^2)*(M23/N23)^4+IF(Z23="",0,INDEX(Parámetros!$E$27:$E$31,MATCH(Z23,Parámetros!$A$27:$A$31,0)))) | V23: Crane fórm. 6 (θ = 180°): contracción y expansión en el inserto | W23: 1.55 | X23: https://latiendadeljardin.com/es/piezas-de-polietileno/445-693-enlace-hembra-pe.html | Y23: Rosca equivalente supuesta (la ficha no la indica) | Z23: MANG | AA23: PE | AB23: =IF(COUNTIFS(Packs!$D$2:$D$70,A23,Packs!$F$2:$F$70,">0")=0,"",_xlfn.MINIFS(Packs!$F$2:$F$70,Packs!$D$2:$D$70,A23,Packs!$F$2:$F$70,">0")) -> 15.4875 | AC23: =COUNTIF(Packs!$D$2:$D$70,A23) -> 1
A24: PE-EH-90 | B24: Enlace rosca hembra PE | C24: 5120 | D24: racor | E24: Enlace compresión × rosca hembra BSP | F24: Compresión × rosca H | G24: 90 | I24: 3" | J24: 16 | K24: PP (cuerpo) · compresión para tubo PE | L24: =INDEX(Parámetros!$D$5:$D$12,MATCH(G24,Parámetros!$A$5:$A$12,0)) -> 73.6 | M24: =INDEX(Parámetros!$D$5:$D$12,MATCH(IF(H24="",G24,H24),Parámetros!$A$5:$A$12,0)) -> 73.6 | N24: =INDEX(Parámetros!$E$5:$E$12,MATCH(G24,Parámetros!$A$5:$A$12,0)) -> 66 | P24: =INDEX(Parámetros!$G$5:$G$12,MATCH(G24,Parámetros!$A$5:$A$12,0)) -> 0.018 | Q24: =IF(Z24="","",INDEX(Parámetros!$C$27:$C$31,MATCH(Z24,Parámetros!$A$27:$A$31,0))*P24) -> 0 | S24: =(Q24+0.5*(1-(N24/L24)^2)+(1-(N24/M24)^2)^2)*(M24/N24)^4+IF(Z24="",0,INDEX(Parámetros!$E$27:$E$31,MATCH(Z24,Parámetros!$A$27:$A$31,0))) -> 0.21076578 | U24: =IF(H24="","",(Q24+0.5*(1-(N24/M24)^2)+(1-(N24/L24)^2)^2)*(M24/N24)^4+IF(Z24="",0,INDEX(Parámetros!$E$27:$E$31,MATCH(Z24,Parámetros!$A$27:$A$31,0)))) | V24: Crane fórm. 6 (θ = 180°): contracción y expansión en el inserto | W24: 1.55 | X24: https://latiendadeljardin.com/es/piezas-de-polietileno/445-693-enlace-hembra-pe.html | Y24: Rosca equivalente supuesta (la ficha no la indica) | Z24: MANG | AA24: PE | AB24: =IF(COUNTIFS(Packs!$D$2:$D$70,A24,Packs!$F$2:$F$70,">0")=0,"",_xlfn.MINIFS(Packs!$F$2:$F$70,Packs!$D$2:$D$70,A24,Packs!$F$2:$F$70,">0")) -> 18.9875 | AC24: =COUNTIF(Packs!$D$2:$D$70,A24) -> 1
A25: PE-EM-20 | B25: Enlace rosca macho PE | C25: 5020 | D25: racor | E25: Enlace compresión × rosca macho BSP | F25: Compresión × rosca M | G25: 20 | I25: 1/2" | J25: 16 | K25: PP (cuerpo) · compresión para tubo PE | L25: =INDEX(Parámetros!$D$5:$D$12,MATCH(G25,Parámetros!$A$5:$A$12,0)) -> 16 | M25: =INDEX(Parámetros!$D$5:$D$12,MATCH(IF(H25="",G25,H25),Parámetros!$A$5:$A$12,0)) -> 16 | N25: =INDEX(Parámetros!$E$5:$E$12,MATCH(G25,Parámetros!$A$5:$A$12,0)) -> 13 | P25: =INDEX(Parámetros!$G$5:$G$12,MATCH(G25,Parámetros!$A$5:$A$12,0)) -> 0.027 | Q25: =IF(Z25="","",INDEX(Parámetros!$C$27:$C$31,MATCH(Z25,Parámetros!$A$27:$A$31,0))*P25) -> 0 | S25: =(Q25+0.5*(1-(N25/L25)^2)+(1-(N25/M25)^2)^2)*(M25/N25)^4+IF(Z25="",0,INDEX(Parámetros!$E$27:$E$31,MATCH(Z25,Parámetros!$A$27:$A$31,0))) -> 0.65491404 | U25: =IF(H25="","",(Q25+0.5*(1-(N25/M25)^2)+(1-(N25/L25)^2)^2)*(M25/N25)^4+IF(Z25="",0,INDEX(Parámetros!$E$27:$E$31,MATCH(Z25,Parámetros!$A$27:$A$31,0)))) | V25: Crane fórm. 6 (θ = 180°): contracción y expansión en el inserto | W25: 1.28 | X25: https://latiendadeljardin.com/es/piezas-de-polietileno/446-701-enlace-macho-pe.html | Y25: Rosca equivalente supuesta (la ficha no la indica) | Z25: MANG | AA25: PE | AB25: =IF(COUNTIFS(Packs!$D$2:$D$70,A25,Packs!$F$2:$F$70,">0")=0,"",_xlfn.MINIFS(Packs!$F$2:$F$70,Packs!$D$2:$D$70,A25,Packs!$F$2:$F$70,">0")) -> 1.7375 | AC25: =COUNTIF(Packs!$D$2:$D$70,A25) -> 1
A26: PE-EM-25 | B26: Enlace rosca macho PE | C26: 5020 | D26: racor | E26: Enlace compresión × rosca macho BSP | F26: Compresión × rosca M | G26: 25 | I26: 3/4" | J26: 16 | K26: PP (cuerpo) · compresión para tubo PE | L26: =INDEX(Parámetros!$D$5:$D$12,MATCH(G26,Parámetros!$A$5:$A$12,0)) -> 20.4 | M26: =INDEX(Parámetros!$D$5:$D$12,MATCH(IF(H26="",G26,H26),Parámetros!$A$5:$A$12,0)) -> 20.4 | N26: =INDEX(Parámetros!$E$5:$E$12,MATCH(G26,Parámetros!$A$5:$A$12,0)) -> 17 | P26: =INDEX(Parámetros!$G$5:$G$12,MATCH(G26,Parámetros!$A$5:$A$12,0)) -> 0.025 | Q26: =IF(Z26="","",INDEX(Parámetros!$C$27:$C$31,MATCH(Z26,Parámetros!$A$27:$A$31,0))*P26) -> 0 | S26: =(Q26+0.5*(1-(N26/L26)^2)+(1-(N26/M26)^2)^2)*(M26/N26)^4+IF(Z26="",0,INDEX(Parámetros!$E$27:$E$31,MATCH(Z26,Parámetros!$A$27:$A$31,0))) -> 0.5104 | U26: =IF(H26="","",(Q26+0.5*(1-(N26/M26)^2)+(1-(N26/L26)^2)^2)*(M26/N26)^4+IF(Z26="",0,INDEX(Parámetros!$E$27:$E$31,MATCH(Z26,Parámetros!$A$27:$A$31,0)))) | V26: Crane fórm. 6 (θ = 180°): contracción y expansión en el inserto | W26: 1.28 | X26: https://latiendadeljardin.com/es/piezas-de-polietileno/446-701-enlace-macho-pe.html | Y26: Rosca equivalente supuesta (la ficha no la indica) | Z26: MANG | AA26: PE | AB26: =IF(COUNTIFS(Packs!$D$2:$D$70,A26,Packs!$F$2:$F$70,">0")=0,"",_xlfn.MINIFS(Packs!$F$2:$F$70,Packs!$D$2:$D$70,A26,Packs!$F$2:$F$70,">0")) -> 2.2375 | AC26: =COUNTIF(Packs!$D$2:$D$70,A26) -> 1
A27: PE-EM-32 | B27: Enlace rosca macho PE | C27: 5020 | D27: racor | E27: Enlace compresión × rosca macho BSP | F27: Compresión × rosca M | G27: 32 | I27: 1" | J27: 16 | K27: PP (cuerpo) · compresión para tubo PE | L27: =INDEX(Parámetros!$D$5:$D$12,MATCH(G27,Parámetros!$A$5:$A$12,0)) -> 26.2 | M27: =INDEX(Parámetros!$D$5:$D$12,MATCH(IF(H27="",G27,H27),Parámetros!$A$5:$A$12,0)) -> 26.2 | N27: =INDEX(Parámetros!$E$5:$E$12,MATCH(G27,Parámetros!$A$5:$A$12,0)) -> 22 | P27: =INDEX(Parámetros!$G$5:$G$12,MATCH(G27,Parámetros!$A$5:$A$12,0)) -> 0.023 | Q27: =IF(Z27="","",INDEX(Parámetros!$C$27:$C$31,MATCH(Z27,Parámetros!$A$27:$A$31,0))*P27) -> 0 | S27: =(Q27+0.5*(1-(N27/L27)^2)+(1-(N27/M27)^2)^2)*(M27/N27)^4+IF(Z27="",0,INDEX(Parámetros!$E$27:$E$31,MATCH(Z27,Parámetros!$A$27:$A$31,0))) -> 0.47154997 | U27: =IF(H27="","",(Q27+0.5*(1-(N27/M27)^2)+(1-(N27/L27)^2)^2)*(M27/N27)^4+IF(Z27="",0,INDEX(Parámetros!$E$27:$E$31,MATCH(Z27,Parámetros!$A$27:$A$31,0)))) | V27: Crane fórm. 6 (θ = 180°): contracción y expansión en el inserto | W27: 1.28 | X27: https://latiendadeljardin.com/es/piezas-de-polietileno/446-701-enlace-macho-pe.html | Y27: Rosca equivalente supuesta (la ficha no la indica) | Z27: MANG | AA27: PE | AB27: =IF(COUNTIFS(Packs!$D$2:$D$70,A27,Packs!$F$2:$F$70,">0")=0,"",_xlfn.MINIFS(Packs!$F$2:$F$70,Packs!$D$2:$D$70,A27,Packs!$F$2:$F$70,">0")) -> 3.4875 | AC27: =COUNTIF(Packs!$D$2:$D$70,A27) -> 1
A28: PE-EM-40 | B28: Enlace rosca macho PE | C28: 5020 | D28: racor | E28: Enlace compresión × rosca macho BSP | F28: Compresión × rosca M | G28: 40 | I28: 1 1/4" | J28: 16 | K28: PP (cuerpo) · compresión para tubo PE | L28: =INDEX(Parámetros!$D$5:$D$12,MATCH(G28,Parámetros!$A$5:$A$12,0)) -> 32.6 | M28: =INDEX(Parámetros!$D$5:$D$12,MATCH(IF(H28="",G28,H28),Parámetros!$A$5:$A$12,0)) -> 32.6 | N28: =INDEX(Parámetros!$E$5:$E$12,MATCH(G28,Parámetros!$A$5:$A$12,0)) -> 28 | P28: =INDEX(Parámetros!$G$5:$G$12,MATCH(G28,Parámetros!$A$5:$A$12,0)) -> 0.022 | Q28: =IF(Z28="","",INDEX(Parámetros!$C$27:$C$31,MATCH(Z28,Parámetros!$A$27:$A$31,0))*P28) -> 0 | S28: =(Q28+0.5*(1-(N28/L28)^2)+(1-(N28/M28)^2)^2)*(M28/N28)^4+IF(Z28="",0,INDEX(Parámetros!$E$27:$E$31,MATCH(Z28,Parámetros!$A$27:$A$31,0))) -> 0.36741629 | U28: =IF(H28="","",(Q28+0.5*(1-(N28/M28)^2)+(1-(N28/L28)^2)^2)*(M28/N28)^4+IF(Z28="",0,INDEX(Parámetros!$E$27:$E$31,MATCH(Z28,Parámetros!$A$27:$A$31,0)))) | V28: Crane fórm. 6 (θ = 180°): contracción y expansión en el inserto | W28: 1.28 | X28: https://latiendadeljardin.com/es/piezas-de-polietileno/446-701-enlace-macho-pe.html | Y28: Rosca equivalente supuesta (la ficha no la indica) | Z28: MANG | AA28: PE | AB28: =IF(COUNTIFS(Packs!$D$2:$D$70,A28,Packs!$F$2:$F$70,">0")=0,"",_xlfn.MINIFS(Packs!$F$2:$F$70,Packs!$D$2:$D$70,A28,Packs!$F$2:$F$70,">0")) -> 4.4875 | AC28: =COUNTIF(Packs!$D$2:$D$70,A28) -> 1
... A32: PE-EM-90 | B32: Enlace rosca macho PE | C32: 5020 | D32: racor | E32: Enlace compresión × rosca macho BSP | F32: Compresión × rosca M | G32: 90 | I32: 3" | J32: 16 | K32: PP (cuerpo) · compresión para tubo PE | L32: =INDEX(Parámetros!$D$5:$D$12,MATCH(G32,Parámetros!$A$5:$A$12,0)) -> 73.6 | M32: =INDEX(Parámetros!$D$5:$D$12,MATCH(IF(H32="",G32,H32),Parámetros!$A$5:$A$12,0)) -> 73.6 | N32: =INDEX(Parámetros!$E$5:$E$12,MATCH(G32,Parámetros!$A$5:$A$12,0)) -> 66 | P32: =INDEX(Parámetros!$G$5:$G$12,MATCH(G32,Parámetros!$A$5:$A$12,0)) -> 0.018 | Q32: =IF(Z32="","",INDEX(Parámetros!$C$27:$C$31,MATCH(Z32,Parámetros!$A$27:$A$31,0))*P32) -> 0 | S32: =(Q32+0.5*(1-(N32/L32)^2)+(1-(N32/M32)^2)^2)*(M32/N32)^4+IF(Z32="",0,INDEX(Parámetros!$E$27:$E$31,MATCH(Z32,Parámetros!$A$27:$A$31,0))) -> 0.21076578 | U32: =IF(H32="","",(Q32+0.5*(1-(N32/M32)^2)+(1-(N32/L32)^2)^2)*(M32/N32)^4+IF(Z32="",0,INDEX(Parámetros!$E$27:$E$31,MATCH(Z32,Parámetros!$A$27:$A$31,0)))) | V32: Crane fórm. 6 (θ = 180°): contracción y expansión en el inserto | W32: 1.28 | X32: https://latiendadeljardin.com/es/piezas-de-polietileno/446-701-enlace-macho-pe.html | Y32: Rosca equivalente supuesta (la ficha no la indica) | Z32: MANG | AA32: PE | AB32: =IF(COUNTIFS(Packs!$D$2:$D$70,A32,Packs!$F$2:$F$70,">0")=0,"",_xlfn.MINIFS(Packs!$F$2:$F$70,Packs!$D$2:$D$70,A32,Packs!$F$2:$F$70,">0")) -> 20.4875 | AC32: =COUNTIF(Packs!$D$2:$D$70,A32) -> 1
A33: PE-CI-20 | B33: Codo igual PE | C33: 5620 | D33: codo90 | E33: Codo 90° de compresión | F33: Compresión × compresión | G33: 20 | J33: 16 | K33: PP (cuerpo) · compresión para tubo PE | L33: =INDEX(Parámetros!$D$5:$D$12,MATCH(G33,Parámetros!$A$5:$A$12,0)) -> 16 | M33: =INDEX(Parámetros!$D$5:$D$12,MATCH(IF(H33="",G33,H33),Parámetros!$A$5:$A$12,0)) -> 16 | N33: =INDEX(Parámetros!$E$5:$E$12,MATCH(G33,Parámetros!$A$5:$A$12,0)) -> 13 | P33: =INDEX(Parámetros!$G$5:$G$12,MATCH(G33,Parámetros!$A$5:$A$12,0)) -> 0.027 | Q33: =IF(Z33="","",INDEX(Parámetros!$C$27:$C$31,MATCH(Z33,Parámetros!$A$27:$A$31,0))*P33) -> 0.81 | S33: =(Q33+0.5*(1-(N33/L33)^2)+(1-(N33/M33)^2)^2)*(M33/N33)^4+IF(Z33="",0,INDEX(Parámetros!$E$27:$E$31,MATCH(Z33,Parámetros!$A$27:$A$31,0))) -> 2.513538 | U33: =IF(H33="","",(Q33+0.5*(1-(N33/M33)^2)+(1-(N33/L33)^2)^2)*(M33/N33)^4+IF(Z33="",0,INDEX(Parámetros!$E$27:$E$31,MATCH(Z33,Parámetros!$A$27:$A$31,0)))) | V33: Crane fórm. 6 con el paso del inserto + codo estándar 30·fT | W33: 2.02 | X33: https://latiendadeljardin.com/es/piezas-de-polietileno/447-709-Codo-igual-pe.html | Z33: CODO | AA33: PE | AB33: =IF(COUNTIFS(Packs!$D$2:$D$70,A33,Packs!$F$2:$F$70,">0")=0,"",_xlfn.MINIFS(Packs!$F$2:$F$70,Packs!$D$2:$D$70,A33,Packs!$F$2:$F$70,">0")) -> 2.2375 | AC33: =COUNTIF(Packs!$D$2:$D$70,A33) -> 1
A34: PE-CI-25 | B34: Codo igual PE | C34: 5620 | D34: codo90 | E34: Codo 90° de compresión | F34: Compresión × compresión | G34: 25 | J34: 16 | K34: PP (cuerpo) · compresión para tubo PE | L34: =INDEX(Parámetros!$D$5:$D$12,MATCH(G34,Parámetros!$A$5:$A$12,0)) -> 20.4 | M34: =INDEX(Parámetros!$D$5:$D$12,MATCH(IF(H34="",G34,H34),Parámetros!$A$5:$A$12,0)) -> 20.4 | N34: =INDEX(Parámetros!$E$5:$E$12,MATCH(G34,Parámetros!$A$5:$A$12,0)) -> 17 | P34: =INDEX(Parámetros!$G$5:$G$12,MATCH(G34,Parámetros!$A$5:$A$12,0)) -> 0.025 | Q34: =IF(Z34="","",INDEX(Parámetros!$C$27:$C$31,MATCH(Z34,Parámetros!$A$27:$A$31,0))*P34) -> 0.75 | S34: =(Q34+0.5*(1-(N34/L34)^2)+(1-(N34/M34)^2)^2)*(M34/N34)^4+IF(Z34="",0,INDEX(Parámetros!$E$27:$E$31,MATCH(Z34,Parámetros!$A$27:$A$31,0))) -> 2.0656 | U34: =IF(H34="","",(Q34+0.5*(1-(N34/M34)^2)+(1-(N34/L34)^2)^2)*(M34/N34)^4+IF(Z34="",0,INDEX(Parámetros!$E$27:$E$31,MATCH(Z34,Parámetros!$A$27:$A$31,0)))) | V34: Crane fórm. 6 con el paso del inserto + codo estándar 30·fT | W34: 2.02 | X34: https://latiendadeljardin.com/es/piezas-de-polietileno/447-709-Codo-igual-pe.html | Z34: CODO | AA34: PE | AB34: =IF(COUNTIFS(Packs!$D$2:$D$70,A34,Packs!$F$2:$F$70,">0")=0,"",_xlfn.MINIFS(Packs!$F$2:$F$70,Packs!$D$2:$D$70,A34,Packs!$F$2:$F$70,">0")) -> 2.7375 | AC34: =COUNTIF(Packs!$D$2:$D$70,A34) -> 1
